Workbook

Sheet CP Tracker Dashboard
A1: Project_Number | B1: CP | C1: Conv Length | D1: Elec Device Count | E1: Mech Install | F1: Elect Install | G1: Path to Run-In | H1: Mech Finishing | I1: As of 6/17/26
A2: B-24-04663 | B2: Total | C2: 641306 | D2: 4951 | E2: 0.027684751 | F2: 0.029549586 | G2: 0.0040651421 | H2: 0
A3: B-24-04663 | B3: CP01 | C3: 28436 | D3: 296 | E3: 0 | F3: 0.02 | G3: 0 | H3: 0
A4: B-24-04663 | B4: CP02 | C4: 41164 | D4: 273 | E4: 0 | F4: 0.02 | G4: 0 | H4: 0
A5: B-24-04663 | B5: CP03 | C5: 37242 | D5: 500 | E5: 0 | F5: 0 | G5: 0 | H5: 0
A6: B-24-04663 | B6: CP09 | C6: 81148 | D6: 150 | E6: 0 | F6: 0.06 | G6: 0 | H6: 0
A7: B-24-04663 | B7: CP11 | C7: 22899 | D7: 175 | E7: 0 | F7: 0.02 | G7: 0 | H7: 0
A8: B-24-04663 | B8: CP40 | C8: 40657 | D8: 496 | E8: 0.24225184 | F8: 0.061814516 | G8: 0 | H8: 0
A9: B-24-04663 | B9: CP41 | C9: 19594 | D9: 425 | E9: 0 | F9: 0.091882353 | G9: 0 | H9: 0
A10: B-24-04663 | B10: CP42 | C10: 14789 | D10: 222 | E10: 0.29523984 | F10: 0.12662162 | G10: 0.17627967 | H10: 0
A11: B-24-04663 | B11: CP50 | C11: 48427 | D11: 500 | E11: 0.073076218 | F11: 0.062 | G11: 0 | H11: 0
A12: B-24-04663 | B12: CP51 | C12: 73424 | D12: 500 | E12: 0 | F12: 0 | G12: 0 | H12: 0
A13: B-24-04663 | B13: CP52 | C13: 148635 | D13: 500 | E13: 0 | F13: 0 | G13: 0 | H13: 0
... A16: B-24-04663 | B16: CP91 | C16: 24847 | D16: 268 | E16: 0 | F16: 0.02 | G16: 0 | H16: 0
A17: Total | C17: 641306 | D17: 4951 | E17: 0.027684751 | F17: 0.036 | G17: 0.0040651421 | H17: 0

Sheet CP40 (2)
A1: CP | B1: Asset | C1: Length | D1: Task Name | E1: Start | F1: Finish | G1: Status | H1: % Complete
A2: CP40 | B2: 40255 | C2: 1 | D2: Staging & Prep | E2: 46146 | F2: 46157 | G2: Complete | H2: 1
A3: CP40 | B3: 40355 | C3: 1 | D3: Staging & Prep | E3: 46146 | F3: 46157 | G3: Complete | H3: 1
A4: CP40 | B4: 40230 | C4: 198 | D4: Staging & Prep | E4: 46146 | F4: 46157 | G4: Complete | H4: 1
A5: CP40 | B5: 40330 | C5: 198 | D5: Staging & Prep | E5: 46146 | F5: 46157 | G5: Complete | H5: 1
A6: CP40 | B6: 40405 | C6: 1 | D6: Staging & Prep | E6: 46146 | F6: 46157 | G6: Complete | H6: 1
A7: CP40 | B7: 40605 | C7: 1 | D7: Staging & Prep | E7: 46146 | F7: 46157 | G7: Not Started | H7: 0
A8: CP40 | B8: 40005 | C8: 1 | D8: Staging & Prep | E8: 46146 | F8: 46157 | G8: Not Started | H8: 0
A9: CP40 | B9: 40010 | C9: 1 | D9: Staging & Prep | E9: 46146 | F9: 46157 | G9: Not Started | H9: 0
A10: CP40 | B10: 40015 | C10: 1 | D10: Staging & Prep | E10: 46146 | F10: 46157 | G10: Not Started | H10: 0
A11: CP40 | B11: 40020 | C11: 1 | D11: Staging & Prep | E11: 46146 | F11: 46157 | G11: Not Started | H11: 0
A12: CP40 | B12: 40025 | C12: 1 | D12: Staging & Prep | E12: 46146 | F12: 46157 | G12: Not Started | H12: 0
A13: CP40 | B13: 40030 | C13: 1 | D13: Staging & Prep | E13: 46146 | F13: 46157 | G13: Not Started | H13: 0
... A35: CP40 | B35: 40320 | C35: 1 | D35: Staging & Prep | E35: 46146 | F35: 46157 | G35: Not Started | H35: 0
A36: CP40 | B36: 40325 | C36: ` | D36: Staging & Prep | E36: 46146 | F36: 46157 | G36: Not Started | H36: 0
A37: CP40 | B37: 40335 | C37: 1 | D37: Staging & Prep | E37: 46146 | F37: 46157 | G37: Not Started | H37: 0
A38: CP40 | B38: 40345 | C38: 1 | D38: Staging & Prep | E38: 46146 | F38: 46157 | G38: Not Started | H38: 0
A39: CP40 | B39: 40348 | C39: 1 | D39: Staging & Prep | E39: 46146 | F39: 46157 | G39: Not Started | H39: 0
A40: CP40 | B40: 40350 | C40: 1 | D40: Staging & Prep | E40: 46146 | F40: 46157 | G40: Not Started | H40: 0
A41: CP40 | B41: 40410 | C41: 1 | D41: Staging & Prep | E41: 46146 | F41: 46157 | G41: Not Started | H41: 0
A42: CP40 | B42: 40415 | C42: 1 | D42: Staging & Prep | E42: 46146 | F42: 46157 | G42: Not Started | H42: 0
A43: CP40 | B43: 40420 | C43: 1 | D43: Staging & Prep | E43: 46146 | F43: 46157 | G43: Not Started | H43: 0
A44: CP40 | B44: 40425 | C44: 1 | D44: Staging & Prep | E44: 46146 | F44: 46157 | G44: Not Started | H44: 0
A45: CP40 | B45: 40430 | C45: 1 | D45: Staging & Prep | E45: 46146 | F45: 46157 | G45: Not Started | H45: 0
A46: CP40 | B46: 40610 | C46: 1 | D46: Staging & Prep | E46: 46146 | F46: 46157 | G46: Not Started | H46: 0
A47: CP40 | B47: 40615 | C47: 1 | D47: Staging & Prep | E47: 46146 | F47: 46157 | G47: Not Started | H47: 0
A48: CP40 | B48: 40620 | C48: 1 | D48: Staging & Prep | E48: 46146 | F48: 46157 | G48: Not Started | H48: 0
... A159: CP40 | B159: 40320 | C159: 1 | D159: Anchored & Leveled | E159: 46170 | F159: 46183 | G159: Not Started | H159: 0
A160: CP40 | B160: 40325 | C160: ` | D160: Anchored & Leveled | E160: 46170 | F160: 46183 | G160: Not Started | H160: 0
A161: CP40 | B161: 40335 | C161: 1 | D161: Anchored & Leveled | E161: 46170 | F161: 46183 | G161: Not Started | H161: 0
A162: CP40 | B162: 40345 | C162: 1 | D162: Anchored & Leveled | E162: 46170 | F162: 46183 | G162: Not Started | H162: 0
A163: CP40 | B163: 40348 | C163: 1 | D163: Anchored & Leveled | E163: 46170 | F163: 46183 | G163: Not Started | H163: 0
A164: CP40 | B164: 40350 | C164: 1 | D164: Anchored & Leveled | E164: 46170 | F164: 46183 | G164: Not Started | H164: 0
A165: CP40 | B165: 40410 | C165: 1 | D165: Anchored & Leveled | E165: 46170 | F165: 46183 | G165: Not Started | H165: 0
A166: CP40 | B166: 40415 | C166: 1 | D166: Anchored & Leveled | E166: 46170 | F166: 46183 | G166: Not Started | H166: 0
A167: CP40 | B167: 40420 | C167: 1 | D167: Anchored & Leveled | E167: 46170 | F167: 46183 | G167: Not Started | H167: 0
A168: CP40 | B168: 40425 | C168: 1 | D168: Anchored & Leveled | E168: 46170 | F168: 46183 | G168: Not Started | H168: 0
A169: CP40 | B169: 40430 | C169: 1 | D169: Anchored & Leveled | E169: 46170 | F169: 46183 | G169: Not Started | H169: 0
A170: CP40 | B170: 40610 | C170: 1 | D170: Anchored & Leveled | E170: 46170 | F170: 46183 | G170: Not Started | H170: 0
A171: CP40 | B171: 40615 | C171: 1 | D171: Anchored & Leveled | E171: 46170 | F171: 46183 | G171: Not Started | H171: 0
...

Sheet CP40 (2) Pivot
A3: Count of Status | B3: Column Labels
A4: Row Labels | B4: Blocked | C4: Complete | D4: Not Started | E4: Grand Total
A5: Anchored & Leveled | C5: 5 | D5: 119 | E5: 124
A6: Belting | D6: 124 | E6: 124
A7: Bottom Pans | D7: 124 | E7: 124
A8: Netting | B8: 124 | E8: 124
A9: Run-in | D9: 124 | E9: 124
A10: Side Guide | D10: 124 | E10: 124
A11: Staging & Prep | C11: 5 | D11: 119 | E11: 124
A12: Grand Total | B12: 124 | C12: 10 | D12: 734 | E12: 868

Sheet AP Tracker Mechanical Dashboard
B2: Overall Totals (As of 6/30/26) - CP52 Not Included
B3: Task | C3: Weight | D3: Weighted Totals | E3: Complete | F3: Complete %
B4: Prep | C4: 0.1 | D4: ='CP40'!C138+'CP41'!C125+'CP42'!C46+'CP50'!C125+'CP51'!C222 -> 59.8 | E4: ='CP40'!D138+'CP41'!D125+'CP42'!D46+'CP50'!D125+'CP51'!D222 -> 23.095 | F4: =E4/D4 -> 0.38620401
B5: Erected | C5: 0.3 | D5: ='CP40'!C139+'CP41'!C126+'CP42'!C47+'CP50'!C126+'CP51'!C223 -> 179.4 | E5: ='CP40'!D139+'CP41'!D126+'CP42'!D47+'CP50'!D126+'CP51'!D223 -> 41.07 | F5: =E5/D5 -> 0.22892977
B6: Anchored | C6: 0.1 | D6: ='CP40'!C140+'CP41'!C127+'CP42'!C48+'CP50'!C127+'CP51'!C224 -> 59.8 | E6: ='CP40'!D140+'CP41'!D127+'CP42'!D48+'CP50'!D127+'CP51'!D224 -> 10.17 | F6: =E6/D6 -> 0.17006689
B7: Belting | C7: 0.2 | D7: ='CP40'!C141+'CP41'!C128+'CP42'!C49+'CP50'!C128+'CP51'!C225 -> 119.6 | E7: ='CP40'!D141+'CP41'!D128+'CP42'!D49+'CP50'!D128+'CP51'!D225 -> 20.14 | F7: =E7/D7 -> 0.16839465
B8: Bottom Pans | C8: 0.05 | D8: ='CP40'!C142+'CP41'!C129+'CP42'!C50+'CP50'!C129+'CP51'!C226 -> 29.9 | E8: ='CP40'!D142+'CP41'!D129+'CP42'!D50+'CP50'!D129+'CP51'!D226 -> 3.67 | F8: =E8/D8 -> 0.12274247
B9: Side Guide | C9: 0.2 | D9: ='CP40'!C143+'CP41'!C130+'CP42'!C51+'CP50'!C130+'CP51'!C227 -> 119.6 | E9: ='CP40'!D143+'CP41'!D130+'CP42'!D51+'CP50'!D130+'CP51'!D227 -> 17.6625 | F9: =E9/D9 -> 0.14767977
B10: Netting | C10: 0.05 | D10: ='CP40'!C144+'CP41'!C131+'CP42'!C52+'CP50'!C131+'CP51'!C228 -> 29.9 | E10: ='CP40'!D144+'CP41'!D131+'CP42'!D52+'CP50'!D131+'CP51'!D228 -> 6.7 | F10: =E10/D10 -> 0.22408027
B11: Total Completion | C11: =SUM(C4:C10) -> 1 | D11: =SUM(D4:D10) -> 598 | E11: =SUM(E4:E10) -> 122.5075 | F11: =E11/D11 -> 0.20486204

Sheet CP40
A1: CP | B1: Asset | C1: Length | D1: Prep -10% | I1: Erected 30% | N1: Anchored 10% | S1: Belting - 20% | X1: Bottom Pans - 5% | AC1: Side Guide - 20% | AH1: Netting - 5% | AM1: Run-in
D2: Start | E2: Finish | F2: Status | G2: Notes | H2: % Complete | I2: Start | J2: Finish | K2: Status | L2: Notes | M2: % Complete | N2: Start | O2: Finish | P2: Status | Q2: Notes | R2: % Complete | S2: Start | T2: Finish | U2: Status | V2: Notes | W2: % Complete | X2: Start | Y2: Finish | Z2: Status | AA2: Notes | AB2: % Complete | AC2: Start | AD2: Finish | AE2: Status | AF2: Notes | AG2: % Complete | AH2: Start | AI2: Finish | AJ2: Status | AK2: Notes | AL2: % Complete | AM2: Start | AN2: Finish | AO2: Status | AP2: % Complete
A3: CP40 | B3: 40255 | C3: 1 | D3: 46146 | E3: 46157 | F3: Complete | G3: Not installed by missing straddle supports | H3: 1 | I3: 46160 | J3: 46169 | K3: Not Started | L3: Missing material Delivery (Straddle Support) | M3: 0 | N3: 46160 | O3: 46169 | P3: Not Started | Q3: Missing material Delivery (Straddle Support) | R3: 1 | S3: 46198 | T3: 46207 | U3: Not Started | V3: Missing material Delivery (Straddle Support) | W3: 0 | X3: 46218 | Y3: 46222 | Z3: Not Started | AA3: Missing material Delivery (Straddle Support) | AB3: 0 | AC3: 46223 | AD3: 46232 | AE3: Not Started | AF3: Missing material Delivery (Straddle Support) | AG3: 0 | AH3: 46243 | AI3: 46250 | AJ3: Blocked | AK3: NA | AL3: 0 | AM3: 46337 | AN3: 46343 | AO3: Not Started | AP3: 0
A4: CP40 | B4: 40355 | C4: 1 | D4: 46146 | E4: 46157 | F4: Complete | G4: Not installed by missing straddle supports | H4: 1 | I4: 46160 | J4: 46169 | K4: Not Started | L4: Missing material Delivery (Straddle Support) | M4: 0 | N4: 46160 | O4: 46169 | P4: Not Started | Q4: Missing material Delivery (Straddle Support) | R4: 1 | S4: 46198 | T4: 46207 | U4: Not Started | V4: Missing material Delivery (Straddle Support) | W4: 0 | X4: 46218 | Y4: 46222 | Z4: Not Started | AA4: Missing material Delivery (Straddle Support) | AB4: 0 | AC4: 46223 | AD4: 46232 | AE4: Not Started | AF4: Missing material Delivery (Straddle Support) | AG4: 0 | AH4: 46243 | AI4: 46250 | AJ4: Blocked | AK4: NA | AL4: 0 | AM4: 46337 | AN4: 46343 | AO4: Not Started | AP4: 0
A5: CP40 | B5: 40230 | C5: 1 | D5: 46146 | E5: 46157 | F5: Complete | H5: 1 | I5: 46160 | J5: 46169 | K5: Complete | L5: Need to replace short supports with correct height | M5: 0.9 | N5: 46160 | O5: 46169 | P5: Complete | Q5: Need to replace short supports with correct height | R5: 1 | S5: 46198 | T5: 46207 | U5: Not Started | V5: 3-Phase to confirm on Belt joining m/c | W5: 0 | X5: 46218 | Y5: 46222 | Z5: Complete | AA5: Complete | AB5: 1 | AC5: 46223 | AD5: 46232 | AE5: Complete | AF5: Complete | AG5: 1 | AH5: 46243 | AI5: 46250 | AJ5: Complete | AK5: NA | AL5: 1 | AM5: 46337 | AN5: 46343 | AO5: Not Started | AP5: 0
A6: CP40 | B6: 40330 | C6: 1 | D6: 46146 | E6: 46157 | F6: Complete | G6: Missing drive | H6: 1 | I6: 46160 | J6: 46169 | K6: Complete | L6: Need to replace short supports with correct height | M6: 0.9 | N6: 46160 | O6: 46169 | P6: Complete | Q6: Need to replace short supports with correct height | R6: 1 | S6: 46198 | T6: 46207 | U6: Not Started | V6: 3-Phase to confirm on Belt joining m/c | W6: 0 | X6: 46218 | Y6: 46222 | Z6: Complete | AA6: Complete | AB6: 1 | AC6: 46223 | AD6: 46232 | AE6: Complete | AF6: Complete | AG6: 1 | AH6: 46243 | AI6: 46250 | AJ6: Complete | AK6: NA | AL6: 1 | AM6: 46337 | AN6: 46343 | AO6: Not Started | AP6: 0
A7: CP40 | B7: 40405 | C7: 1 | D7: 46146 | E7: 46157 | F7: Complete | H7: 1 | I7: 46160 | J7: 46169 | K7: Complete | L7: Complete | M7: 1 | N7: 46160 | O7: 46169 | P7: Complete | Q7: Complete | R7: 1 | S7: 46198 | T7: 46207 | U7: Complete | V7: Complete | W7: 1 | X7: 46218 | Y7: 46222 | Z7: Complete | AA7: Complete | AB7: 1 | AC7: 46223 | AD7: 46232 | AE7: Complete | AF7: Complete | AG7: 1 | AH7: 46243 | AI7: 46250 | AJ7: Complete | AK7: NA | AL7: 1 | AM7: 46337 | AN7: 46343 | AO7: Not Started | AP7: 0
A8: CP40 | B8: 40605 | C8: 1 | D8: 46146 | E8: 46157 | F8: Complete | H8: 1 | I8: 46160 | J8: 46169 | K8: Complete | L8: Complete | M8: 1 | N8: 46160 | O8: 46169 | P8: Complete | Q8: Complete | R8: 1 | S8: 46198 | T8: 46207 | U8: Complete | V8: Complete | W8: 1 | X8: 46218 | Y8: 46222 | Z8: Complete | AA8: Complete | AB8: 1 | AC8: 46223 | AD8: 46232 | AE8: Complete | AF8: Complete | AG8: 1 | AH8: 46243 | AI8: 46250 | AJ8: Complete | AK8: NA | AL8: 1 | AM8: 46337 | AN8: 46343 | AO8: Not Started | AP8: 0
A9: CP40 | B9: 40005 | C9: 1 | D9: 46146 | E9: 46157 | F9: Complete | H9: 1 | I9: 46160 | J9: 46169 | K9: Not Started | L9: Area Beyond Grid 8 ,not available for Install | M9: 0 | N9: 46160 | O9: 46169 | P9: Not Started | Q9: Area Beyond Grid 8 ,not available for Install | R9: 0 | S9: 46198 | T9: 46207 | U9: Not Started | V9: Area Beyond Grid 8 ,not available for Install | W9: 0 | X9: 46218 | Y9: 46222 | Z9: Not Started | AA9: Area Beyond Grid 8 ,not available for Install | AB9: 0 | AC9: 46223 | AD9: 46232 | AE9: Not Started | AF9: Area Beyond Grid 8 ,not available for Install | AG9: 0 | AH9: 46243 | AI9: 46250 | AJ9: Blocked | AK9: Area Beyond Grid 8 ,not available for Install | AL9: 0 | AM9: 46337 | AN9: 46343 | AO9: Not Started | AP9: 0
A10: CP40 | B10: 40010 | C10: 1 | D10: 46146 | E10: 46157 | F10: Complete | H10: 1 | I10: 46160 | J10: 46169 | K10: Not Started | L10: Area Beyond Grid 8 ,not available for Install | M10: 0 | N10: 46160 | O10: 46169 | P10: Not Started | Q10: Area Beyond Grid 8 ,not available for Install | R10: 0 | S10: 46198 | T10: 46207 | U10: Not Started | V10: Area Beyond Grid 8 ,not available for Install | W10: 0 | X10: 46218 | Y10: 46222 | Z10: Not Started | AA10: Area Beyond Grid 8 ,not available for Install | AB10: 0 | AC10: 46223 | AD10: 46232 | AE10: Not Started | AF10: Area Beyond Grid 8 ,not available for Install | AG10: 0 | AH10: 46243 | AI10: 46250 | AJ10: Blocked | AK10: Area Beyond Grid 8 ,not available for Install | AL10: 0 | AM10: 46337 | AN10: 46343 | AO10: Not Started | AP10: 0
A11: CP40 | B11: 40015 | C11: 1 | D11: 46146 | E11: 46157 | F11: Complete | H11: 1 | I11: 46160 | J11: 46169 | K11: Not Started | L11: Area Beyond Grid 8 ,not available for Install | M11: 0 | N11: 46160 | O11: 46169 | P11: Not Started | Q11: Area Beyond Grid 8 ,not available for Install | R11: 0 | S11: 46198 | T11: 46207 | U11: Not Started | V11: Area Beyond Grid 8 ,not available for Install | W11: 0 | X11: 46218 | Y11: 46222 | Z11: Not Started | AA11: Area Beyond Grid 8 ,not available for Install | AB11: 0 | AC11: 46223 | AD11: 46232 | AE11: Not Started | AF11: Area Beyond Grid 8 ,not available for Install | AG11: 0 | AH11: 46243 | AI11: 46250 | AJ11: Blocked | AK11: Area Beyond Grid 8 ,not available for Install | AL11: 0 | AM11: 46337 | AN11: 46343 | AO11: Not Started | AP11: 0
A12: CP40 | B12: 40020 | C12: 1 | D12: 46146 | E12: 46157 | F12: Complete | G12: 40036700-11209549 | H12: 0.9 | I12: 46160 | J12: 46169 | K12: Not Started | L12: Area Beyond Grid 8 ,not available for Install | M12: 0 | N12: 46160 | O12: 46169 | P12: Not Started | Q12: Area Beyond Grid 8 ,not available for Install | R12: 0 | S12: 46198 | T12: 46207 | U12: Not Started | V12: Area Beyond Grid 8 ,not available for Install | W12: 0 | X12: 46218 | Y12: 46222 | Z12: Not Started | AA12: Area Beyond Grid 8 ,not available for Install | AB12: 0 | AC12: 46223 | AD12: 46232 | AE12: Not Started | AF12: Area Beyond Grid 8 ,not available for Install | AG12: 0 | AH12: 46243 | AI12: 46250 | AJ12: Blocked | AK12: Area Beyond Grid 8 ,not available for Install | AL12: 0 | AM12: 46337 | AN12: 46343 | AO12: Not Started | AP12: 0
A13: CP40 | B13: 40025 | C13: 1 | D13: 46146 | E13: 46157 | F13: Complete | H13: 0.6 | I13: 46160 | J13: 46169 | K13: Not Started | L13: Area Beyond Grid 8 ,not available for Install | M13: 0 | N13: 46160 | O13: 46169 | P13: Not Started | Q13: Area Beyond Grid 8 ,not available for Install | R13: 0 | S13: 46198 | T13: 46207 | U13: Not Started | V13: Area Beyond Grid 8 ,not available for Install | W13: 0 | X13: 46218 | Y13: 46222 | Z13: Not Started | AA13: Area Beyond Grid 8 ,not available for Install | AB13: 0 | AC13: 46223 | AD13: 46232 | AE13: Not Started | AF13: Area Beyond Grid 8 ,not available for Install | AG13: 0 | AH13: 46243 | AI13: 46250 | AJ13: Blocked | AK13: Area Beyond Grid 8 ,not available for Install | AL13: 0 | AM13: 46337 | AN13: 46343 | AO13: Not Started | AP13: 0
A14: CP40 | B14: 40030 | C14: 1 | D14: 46146 | E14: 46157 | F14: Complete | H14: 1 | I14: 46160 | J14: 46169 | K14: Not Started | L14: Area Beyond Grid 8 ,not available for Install | M14: 0 | N14: 46160 | O14: 46169 | P14: Not Started | Q14: Area Beyond Grid 8 ,not available for Install | R14: 0 | S14: 46198 | T14: 46207 | U14: Not Started | V14: Area Beyond Grid 8 ,not available for Install | W14: 0 | X14: 46218 | Y14: 46222 | Z14: Not Started | AA14: Area Beyond Grid 8 ,not available for Install | AB14: 0 | AC14: 46223 | AD14: 46232 | AE14: Not Started | AF14: Area Beyond Grid 8 ,not available for Install | AG14: 0 | AH14: 46243 | AI14: 46250 | AJ14: Blocked | AK14: Area Beyond Grid 8 ,not available for Install | AL14: 0 | AM14: 46337 | AN14: 46343 | AO14: Not Started | AP14: 0
A15: CP40 | B15: 40105 | C15: 1 | D15: 46146 | E15: 46157 | F15: Complete | G15: 47039800-9636785 | H15: 0.9 | I15: 46160 | J15: 46169 | K15: Not Started | L15: Area Beyond Grid 8 ,not available for Install | M15: 0 | N15: 46160 | O15: 46169 | P15: Not Started | Q15: Area Beyond Grid 8 ,not available for Install | R15: 0 | S15: 46198 | T15: 46207 | U15: Not Started | V15: Area Beyond Grid 8 ,not available for Install | W15: 0 | X15: 46218 | Y15: 46222 | Z15: Not Started | AA15: Area Beyond Grid 8 ,not available for Install | AB15: 0 | AC15: 46223 | AD15: 46232 | AE15: Not Started | AF15: Area Beyond Grid 8 ,not available for Install | AG15: 0 | AH15: 46243 | AI15: 46250 | AJ15: Blocked | AK15: Area Beyond Grid 8 ,not available for Install | AL15: 0 | AM15: 46337 | AN15: 46343 | AO15: Not Started | AP15: 0
A16: CP40 | B16: 40110 | C16: 1 | D16: 46146 | E16: 46157 | F16: Complete | G16: 47007400-11209515 | H16: 0.9 | I16: 46160 | J16: 46169 | K16: Not Started | L16: Area Beyond Grid 8 ,not available for Install | M16: 0 | N16: 46160 | O16: 46169 | P16: Not Started | Q16: Area Beyond Grid 8 ,not available for Install | R16: 0 | S16: 46198 | T16: 46207 | U16: Not Started | V16: Area Beyond Grid 8 ,not available for Install | W16: 0 | X16: 46218 | Y16: 46222 | Z16: Not Started | AA16: Area Beyond Grid 8 ,not available for Install | AB16: 0 | AC16: 46223 | AD16: 46232 | AE16: Not Started | AF16: Area Beyond Grid 8 ,not available for Install | AG16: 0 | AH16: 46243 | AI16: 46250 | AJ16: Blocked | AK16: Area Beyond Grid 8 ,not available for Install | AL16: 0 | AM16: 46337 | AN16: 46343 | AO16: Not Started | AP16: 0
A17: CP40 | B17: 40115 | C17: 1 | D17: 46146 | E17: 46157 | F17: Complete | H17: 1 | I17: 46160 | J17: 46169 | K17: Not Started | L17: Area Beyond Grid 8 ,not available for Install | M17: 0 | N17: 46160 | O17: 46169 | P17: Not Started | Q17: Area Beyond Grid 8 ,not available for Install | R17: 0 | S17: 46198 | T17: 46207 | U17: Not Started | V17: Area Beyond Grid 8 ,not available for Install | W17: 0 | X17: 46218 | Y17: 46222 | Z17: Not Started | AA17: Area Beyond Grid 8 ,not available for Install | AB17: 0 | AC17: 46223 | AD17: 46232 | AE17: Not Started | AF17: Area Beyond Grid 8 ,not available for Install | AG17: 0 | AH17: 46243 | AI17: 46250 | AJ17: Blocked | AK17: Area Beyond Grid 8 ,not available for Install | AL17: 0 | AM17: 46337 | AN17: 46343 | AO17: Not Started | AP17: 0
A18: CP40 | B18: 40120 | C18: 1 | D18: 46146 | E18: 46157 | F18: Complete | H18: 1 | I18: 46160 | J18: 46169 | K18: Not Started | L18: Area Beyond Grid 8 ,not available for Install | M18: 0 | N18: 46160 | O18: 46169 | P18: Not Started | Q18: Area Beyond Grid 8 ,not available for Install | R18: 0 | S18: 46198 | T18: 46207 | U18: Not Started | V18: Area Beyond Grid 8 ,not available for Install | W18: 0 | X18: 46218 | Y18: 46222 | Z18: Not Started | AA18: Area Beyond Grid 8 ,not available for Install | AB18: 0 | AC18: 46223 | AD18: 46232 | AE18: Not Started | AF18: Area Beyond Grid 8 ,not available for Install | AG18: 0 | AH18: 46243 | AI18: 46250 | AJ18: Blocked | AK18: Area Beyond Grid 8 ,not available for Install | AL18: 0 | AM18: 46337 | AN18: 46343 | AO18: Not Started | AP18: 0
A19: CP40 | B19: 40125 | C19: 1 | D19: 46146 | E19: 46157 | F19: Complete | G19: 49253330-11554036 | H19: 0.9 | I19: 46160 | J19: 46169 | K19: Not Started | L19: Area Beyond Grid 8 ,not available for Install | M19: 0 | N19: 46160 | O19: 46169 | P19: Not Started | Q19: Area Beyond Grid 8 ,not available for Install | R19: 0 | S19: 46198 | T19: 46207 | U19: Not Started | V19: Area Beyond Grid 8 ,not available for Install | W19: 0 | X19: 46218 | Y19: 46222 | Z19: Not Started | AA19: Area Beyond Grid 8 ,not available for Install | AB19: 0 | AC19: 46223 | AD19: 46232 | AE19: Not Started | AF19: Area Beyond Grid 8 ,not available for Install | AG19: 0 | AH19: 46243 | AI19: 46250 | AJ19: Blocked | AK19: Area Beyond Grid 8 ,not available for Install | AL19: 0 | AM19: 46337 | AN19: 46343 | AO19: Not Started | AP19: 0
A20: CP40 | B20: 40130 | C20: 1 | D20: 46146 | E20: 46157 | F20: Complete | H20: 1 | I20: 46160 | J20: 46169 | K20: Not Started | L20: Area Beyond Grid 8 ,not available for Install | M20: 0 | N20: 46160 | O20: 46169 | P20: Not Started | Q20: Area Beyond Grid 8 ,not available for Install | R20: 0.5 | S20: 46198 | T20: 46207 | U20: Not Started | V20: Area Beyond Grid 8 ,not available for Install | W20: 0 | X20: 46218 | Y20: 46222 | Z20: Not Started | AA20: Area Beyond Grid 8 ,not available for Install | AB20: 0 | AC20: 46223 | AD20: 46232 | AE20: Not Started | AF20: Area Beyond Grid 8 ,not available for Install | AG20: 0 | AH20: 46243 | AI20: 46250 | AJ20: Blocked | AK20: Area Beyond Grid 8 ,not available for Install | AL20: 0 | AM20: 46337 | AN20: 46343 | AO20: Not Started | AP20: 0
A21: CP40 | B21: 40205 | C21: 1 | D21: 46146 | E21: 46157 | F21: Complete | H21: 1 | I21: 46160 | J21: 46169 | K21: Not Started | L21: Area Beyond Grid 8 ,not available for Install | M21: 0 | N21: 46160 | O21: 46169 | P21: Not Started | Q21: Area Beyond Grid 8 ,not available for Install | R21: 0 | S21: 46198 | T21: 46207 | U21: Not Started | V21: Area Beyond Grid 8 ,not available for Install | W21: 0 | X21: 46218 | Y21: 46222 | Z21: Not Started | AA21: Area Beyond Grid 8 ,not available for Install | AB21: 0 | AC21: 46223 | AD21: 46232 | AE21: Not Started | AF21: Area Beyond Grid 8 ,not available for Install | AG21: 0 | AH21: 46243 | AI21: 46250 | AJ21: Blocked | AK21: Area Beyond Grid 8 ,not available for Install | AL21: 0 | AM21: 46337 | AN21: 46343 | AO21: Not Started | AP21: 0
A22: CP40 | B22: 40210 | C22: 1 | D22: 46146 | E22: 46157 | F22: Complete | H22: 1 | I22: 46160 | J22: 46169 | K22: Not Started | L22: Area Beyond Grid 8 ,not available for Install | M22: 0 | N22: 46160 | O22: 46169 | P22: Not Started | Q22: Area Beyond Grid 8 ,not available for Install | R22: 0 | S22: 46198 | T22: 46207 | U22: Not Started | V22: Area Beyond Grid 8 ,not available for Install | W22: 0 | X22: 46218 | Y22: 46222 | Z22: Not Started | AA22: Area Beyond Grid 8 ,not available for Install | AB22: 0 | AC22: 46223 | AD22: 46232 | AE22: Not Started | AF22: Area Beyond Grid 8 ,not available for Install | AG22: 0 | AH22: 46243 | AI22: 46250 | AJ22: Blocked | AK22: Area Beyond Grid 8 ,not available for Install | AL22: 0 | AM22: 46337 | AN22: 46343 | AO22: Not Started | AP22: 0
A23: CP40 | B23: 40215 | C23: 1 | D23: 46146 | E23: 46157 | F23: Complete | H23: 1 | I23: 46160 | J23: 46169 | K23: Not Started | L23: Area Beyond Grid 8 ,not available for Install | M23: 0 | N23: 46160 | O23: 46169 | P23: Not Started | Q23: Area Beyond Grid 8 ,not available for Install | R23: 0 | S23: 46198 | T23: 46207 | U23: Not Started | V23: Area Beyond Grid 8 ,not available for Install | W23: 0 | X23: 46218 | Y23: 46222 | Z23: Not Started | AA23: Area Beyond Grid 8 ,not available for Install | AB23: 0 | AC23: 46223 | AD23: 46232 | AE23: Not Started | AF23: Area Beyond Grid 8 ,not available for Install | AG23: 0 | AH23: 46243 | AI23: 46250 | AJ23: Blocked | AK23: Area Beyond Grid 8 ,not available for Install | AL23: 0 | AM23: 46337 | AN23: 46343 | AO23: Not Started | AP23: 0
A24: CP40 | B24: 40220 | C24: 1 | D24: 46146 | E24: 46157 | F24: Complete | H24: 1 | I24: 46160 | J24: 46169 | K24: Not Started | L24: Area Beyond Grid 8 ,not available for Install | M24: 0 | N24: 46160 | O24: 46169 | P24: Not Started | Q24: Area Beyond Grid 8 ,not available for Install | R24: 0 | S24: 46198 | T24: 46207 | U24: Not Started | V24: Area Beyond Grid 8 ,not available for Install | W24: 0 | X24: 46218 | Y24: 46222 | Z24: Not Started | AA24: Area Beyond Grid 8 ,not available for Install | AB24: 0 | AC24: 46223 | AD24: 46232 | AE24: Not Started | AF24: Area Beyond Grid 8 ,not available for Install | AG24: 0 | AH24: 46243 | AI24: 46250 | AJ24: Blocked | AK24: Area Beyond Grid 8 ,not available for Install | AL24: 0 | AM24: 46337 | AN24: 46343 | AO24: Not Started | AP24: 0
A25: CP40 | B25: 40225 | C25: 1 | D25: 46146 | E25: 46157 | F25: Complete | H25: 1 | I25: 46160 | J25: 46169 | K25: Not Started | L25: Area Beyond Grid 8 ,not available for Install | M25: 0 | N25: 46160 | O25: 46169 | P25: Not Started | Q25: Area Beyond Grid 8 ,not available for Install | R25: 0 | S25: 46198 | T25: 46207 | U25: Not Started | V25: Area Beyond Grid 8 ,not available for Install | W25: 0 | X25: 46218 | Y25: 46222 | Z25: Not Started | AA25: Area Beyond Grid 8 ,not available for Install | AB25: 0 | AC25: 46223 | AD25: 46232 | AE25: Not Started | AF25: Area Beyond Grid 8 ,not available for Install | AG25: 0 | AH25: 46243 | AI25: 46250 | AJ25: Blocked | AK25: Area Beyond Grid 8 ,not available for Install | AL25: 0 | AM25: 46337 | AN25: 46343 | AO25: Not Started | AP25: 0
A26: CP40 | B26: 40235 | C26: 1 | D26: 46146 | E26: 46157 | F26: Complete | G26: Not installed by missing straddle supports | H26: 0.6 | I26: 46160 | J26: 46169 | K26: Not Started | L26: Missing material Delivery (Straddle Support) | M26: 0 | N26: 46160 | O26: 46169 | P26: Not Started | Q26: Missing material Delivery (Straddle Support) | R26: 0 | S26: 46198 | T26: 46207 | U26: Not Started | V26: Missing material Delivery (Straddle Support) | W26: 0 | X26: 46218 | Y26: 46222 | Z26: Not Started | AA26: Missing material Delivery (Straddle Support) | AB26: 0 | AC26: 46223 | AD26: 46232 | AE26: Not Started | AF26: Missing material Delivery (Straddle Support) | AG26: 0 | AH26: 46243 | AI26: 46250 | AJ26: Blocked | AK26: Missing material Delivery | AL26: 0 | AM26: 46337 | AN26: 46343 | AO26: Not Started | AP26: 0
A27: CP40 | B27: 40245 | C27: 1 | D27: 46146 | E27: 46157 | F27: Not Started | G27: PBC NO INFO ISC | H27: 0 | I27: 46160 | J27: 46169 | K27: Not Started | L27: Missing material delivery (Transnorm Curve) | M27: 0 | N27: 46160 | O27: 46169 | P27: Not Started | Q27: Missing material delivery (Transnorm Curve) | R27: 0 | S27: 46198 | T27: 46207 | U27: Not Started | V27: Missing material delivery (Transnorm Curve) | W27: 0 | X27: 46218 | Y27: 46222 | Z27: Not Started | AA27: Missing material delivery (Transnorm Curve) | AB27: 0 | AC27: 46223 | AD27: 46232 | AE27: Not Started | AF27: Missing material delivery (Transnorm Curve) | AG27: 0 | AH27: 46243 | AI27: 46250 | AJ27: Blocked | AK27: NA | AL27: 0 | AM27: 46337 | AN27: 46343 | AO27: Not Started | AP27: 0
A28: CP40 | B28: 40248 | C28: 1 | D28: 46146 | E28: 46157 | F28: Complete | G28: 47012000-11417507 | H28: 0.9 | I28: 46160 | J28: 46169 | K28: Not Started | L28: Upstream & Downstream conveyor not installed | M28: 0 | N28: 46160 | O28: 46169 | P28: Not Started | Q28: Upstream & Downstream conveyor not installed | R28: 0.5 | S28: 46198 | T28: 46207 | U28: Not Started | V28: Upstream & Downstream conveyor not installed | W28: 0 | X28: 46218 | Y28: 46222 | Z28: Not Started | AA28: Waiting for installation | AB28: 0 | AC28: 46223 | AD28: 46232 | AE28: Not Started | AF28: Upstream & Downstream conveyor not installed | AG28: 0 | AH28: 46243 | AI28: 46250 | AJ28: Blocked | AK28: NA | AL28: 0 | AM28: 46337 | AN28: 46343 | AO28: Not Started | AP28: 0
A29: CP40 | B29: 40250 | C29: 1 | D29: 46146 | E29: 46157 | F29: Complete | G29: wrong hand | H29: 0.9 | I29: 46160 | J29: 46169 | K29: Not Started | L29: Upstream & Downstream conveyor not installed | M29: 0 | N29: 46160 | O29: 46169 | P29: Not Started | Q29: Upstream & Downstream conveyor not installed | R29: 0.9 | S29: 46198 | T29: 46207 | U29: Complete | V29: Upstream & Downstream conveyor not installed | W29: 1 | X29: 46218 | Y29: 46222 | Z29: Not Started | AA29: Upstream & Downstream conveyor not installed | AB29: 0 | AC29: 46223 | AD29: 46232 | AE29: Not Started | AF29: Upstream & Downstream conveyor not installed | AG29: 0 | AH29: 46243 | AI29: 46250 | AJ29: Blocked | AK29: NA | AL29: 0 | AM29: 46337 | AN29: 46343 | AO29: Not Started | AP29: 0
A30: CP40 | B30: 40305 | C30: 1 | D30: 46146 | E30: 46157 | F30: Complete | H30: 1 | I30: 46160 | J30: 46169 | K30: Not Started | L30: Area Beyond Grid 8 ,not available for Install | M30: 0 | N30: 46160 | O30: 46169 | P30: Not Started | Q30: Area Beyond Grid 8 ,not available for Install | R30: 0 | S30: 46198 | T30: 46207 | U30: Not Started | V30: Area Beyond Grid 8 ,not available for Install | W30: 0 | X30: 46218 | Y30: 46222 | Z30: Not Started | AA30: Area Beyond Grid 8 ,not available for Install | AB30: 0 | AC30: 46223 | AD30: 46232 | AE30: Not Started | AF30: Area Beyond Grid 8 ,not available for Install | AG30: 0 | AH30: 46243 | AI30: 46250 | AJ30: Blocked | AK30: Area Beyond Grid 8 ,not available for Install | AL30: 0 | AM30: 46337 | AN30: 46343 | AO30: Not Started | AP30: 0
A31: CP40 | B31: 40310 | C31: 1 | D31: 46146 | E31: 46157 | F31: Complete | H31: 1 | I31: 46160 | J31: 46169 | K31: Not Started | L31: Area Beyond Grid 8 ,not available for Install | M31: 0 | N31: 46160 | O31: 46169 | P31: Not Started | Q31: Area Beyond Grid 8 ,not available for Install | R31: 0 | S31: 46198 | T31: 46207 | U31: Not Started | V31: Area Beyond Grid 8 ,not available for Install | W31: 0 | X31: 46218 | Y31: 46222 | Z31: Not Started | AA31: Area Beyond Grid 8 ,not available for Install | AB31: 0 | AC31: 46223 | AD31: 46232 | AE31: Not Started | AF31: Area Beyond Grid 8 ,not available for Install | AG31: 0 | AH31: 46243 | AI31: 46250 | AJ31: Blocked | AK31: Area Beyond Grid 8 ,not available for Install | AL31: 0 | AM31: 46337 | AN31: 46343 | AO31: Not Started | AP31: 0
A32: CP40 | B32: 40312 | C32: 1 | D32: 46146 | E32: 46157 | F32: Complete | H32: 1 | I32: 46160 | J32: 46169 | K32: Not Started | L32: Area Beyond Grid 8 ,not available for Install | M32: 0 | N32: 46160 | O32: 46169 | P32: Not Started | Q32: Area Beyond Grid 8 ,not available for Install | R32: 0 | S32: 46198 | T32: 46207 | U32: Not Started | V32: Area Beyond Grid 8 ,not available for Install | W32: 0 | X32: 46218 | Y32: 46222 | Z32: Not Started | AA32: Area Beyond Grid 8 ,not available for Install | AB32: 0 | AC32: 46223 | AD32: 46232 | AE32: Not Started | AF32: Area Beyond Grid 8 ,not available for Install | AG32: 0 | AH32: 46243 | AI32: 46250 | AJ32: Blocked | AK32: Area Beyond Grid 8 ,not available for Install | AL32: 0 | AM32: 46337 | AN32: 46343 | AO32: Not Started | AP32: 0
A33: CP40 | B33: 40314 | C33: 1 | D33: 46146 | E33: 46157 | F33: Complete | H33: 1 | I33: 46160 | J33: 46169 | K33: Not Started | L33: Area Beyond Grid 8 ,not available for Install | M33: 0 | N33: 46160 | O33: 46169 | P33: Not Started | Q33: Area Beyond Grid 8 ,not available for Install | R33: 0 | S33: 46198 | T33: 46207 | U33: Not Started | V33: Area Beyond Grid 8 ,not available for Install | W33: 0 | X33: 46218 | Y33: 46222 | Z33: Not Started | AA33: Area Beyond Grid 8 ,not available for Install | AB33: 0 | AC33: 46223 | AD33: 46232 | AE33: Not Started | AF33: Area Beyond Grid 8 ,not available for Install | AG33: 0 | AH33: 46243 | AI33: 46250 | AJ33: Blocked | AK33: Area Beyond Grid 8 ,not available for Install | AL33: 0 | AM33: 46337 | AN33: 46343 | AO33: Not Started | AP33: 0
A34: CP40 | B34: 40316 | C34: 1 | D34: 46146 | E34: 46157 | F34: Complete | H34: 1 | I34: 46170 | J34: 46183 | K34: Not Started | L34: Area Beyond Grid 8 ,not available for Install | M34: 0 | N34: 46170 | O34: 46183 | P34: Not Started | Q34: Area Beyond Grid 8 ,not available for Install | R34: 0 | S34: 46198 | T34: 46207 | U34: Not Started | V34: Area Beyond Grid 8 ,not available for Install | W34: 0 | X34: 46218 | Y34: 46222 | Z34: Not Started | AA34: Area Beyond Grid 8 ,not available for Install | AB34: 0 | AC34: 46223 | AD34: 46232 | AE34: Not Started | AF34: Area Beyond Grid 8 ,not available for Install | AG34: 0 | AH34: 46243 | AI34: 46250 | AJ34: Blocked | AK34: Area Beyond Grid 8 ,not available for Install | AL34: 0 | AM34: 46337 | AN34: 46343 | AO34: Not Started | AP34: 0
A35: CP40 | B35: 40318 | C35: 1 | D35: 46146 | E35: 46157 | F35: Complete | H35: 1 | I35: 46170 | J35: 46183 | K35: Not Started | L35: Area Beyond Grid 8 ,not available for Install | M35: 0 | N35: 46170 | O35: 46183 | P35: Not Started | Q35: Area Beyond Grid 8 ,not available for Install | R35: 0 | S35: 46198 | T35: 46207 | U35: Not Started | V35: Area Beyond Grid 8 ,not available for Install | W35: 0 | X35: 46218 | Y35: 46222 | Z35: Not Started | AA35: Area Beyond Grid 8 ,not available for Install | AB35: 0 | AC35: 46223 | AD35: 46232 | AE35: Not Started | AF35: Area Beyond Grid 8 ,not available for Install | AG35: 0 | AH35: 46243 | AI35: 46250 | AJ35: Blocked | AK35: Area Beyond Grid 8 ,not available for Install | AL35: 0 | AM35: 46337 | AN35: 46343 | AO35: Not Started | AP35: 0
A36: CP40 | B36: 40320 | C36: 1 | D36: 46146 | E36: 46157 | F36: Complete | G36: 47007400-11209531 | H36: 0.9 | I36: 46170 | J36: 46183 | K36: Not Started | L36: Area Beyond Grid 8 ,not available for Install | M36: 0 | N36: 46170 | O36: 46183 | P36: Not Started | Q36: Area Beyond Grid 8 ,not available for Install | R36: 0 | S36: 46198 | T36: 46207 | U36: Not Started | V36: Area Beyond Grid 8 ,not available for Install | W36: 0 | X36: 46218 | Y36: 46222 | Z36: Not Started | AA36: Area Beyond Grid 8 ,not available for Install | AB36: 0 | AC36: 46223 | AD36: 46232 | AE36: Not Started | AF36: Area Beyond Grid 8 ,not available for Install | AG36: 0 | AH36: 46243 | AI36: 46250 | AJ36: Blocked | AK36: Area Beyond Grid 8 ,not available for Install | AL36: 0 | AM36: 46337 | AN36: 46343 | AO36: Not Started | AP36: 0
A37: CP40 | B37: 40325 | C37: 1 | D37: 46146 | E37: 46157 | F37: Complete | H37: 0.8 | I37: 46170 | J37: 46183 | K37: Not Started | L37: Area Beyond Grid 8 ,not available for Install | M37: 0 | N37: 46170 | O37: 46183 | P37: Not Started | Q37: Area Beyond Grid 8 ,not available for Install | R37: 0 | S37: 46198 | T37: 46207 | U37: Not Started | V37: Area Beyond Grid 8 ,not available for Install | W37: 0 | X37: 46218 | Y37: 46222 | Z37: Not Started | AA37: Area Beyond Grid 8 ,not available for Install | AB37: 0 | AC37: 46223 | AD37: 46232 | AE37: Not Started | AF37: Area Beyond Grid 8 ,not available for Install | AG37: 0 | AH37: 46243 | AI37: 46250 | AJ37: Blocked | AK37: Area Beyond Grid 8 ,not available for Install | AL37: 0 | AM37: 46337 | AN37: 46343 | AO37: Not Started | AP37: 0
A38: CP40 | B38: 40335 | C38: 1 | D38: 46146 | E38: 46157 | F38: Complete | G38: Not installed by missing straddle supports | H38: 1 | I38: 46170 | J38: 46183 | K38: Not Started | L38: Missing material Delivery (Straddle Support) | M38: 0 | N38: 46170 | O38: 46183 | P38: Not Started | Q38: Missing material Delivery (Straddle Support) | R38: 0 | S38: 46198 | T38: 46207 | U38: Not Started | V38: Missing material Delivery (Straddle Support) | W38: 0 | X38: 46218 | Y38: 46222 | Z38: Not Started | AA38: Missing material Delivery (Straddle Support) | AB38: 0 | AC38: 46223 | AD38: 46232 | AE38: Not Started | AF38: Missing material Delivery (Straddle Support) | AG38: 0 | AH38: 46243 | AI38: 46250 | AJ38: Blocked | AK38: Missing material Delivery | AL38: 0 | AM38: 46337 | AN38: 46343 | AO38: Not Started | AP38: 0
A39: CP40 | B39: 40345 | C39: 1 | D39: 46146 | E39: 46157 | F39: Not Started | G39: PBC NO INFO ISC | H39: 0 | I39: 46170 | J39: 46183 | K39: Not Started | L39: Missing material delivery (Transnorm Curve) | M39: 0 | N39: 46170 | O39: 46183 | P39: Not Started | Q39: Missing material delivery (Transnorm Curve) | R39: 0 | S39: 46198 | T39: 46207 | U39: Not Started | V39: Missing material delivery (Transnorm Curve) | W39: 0 | X39: 46218 | Y39: 46222 | Z39: Not Started | AA39: Missing material delivery (Transnorm Curve) | AB39: 0 | AC39: 46223 | AD39: 46232 | AE39: Not Started | AF39: Missing material delivery (Transnorm Curve) | AG39: 0 | AH39: 46243 | AI39: 46250 | AJ39: Blocked | AK39: NA | AL39: 0 | AM39: 46337 | AN39: 46343 | AO39: Not Started | AP39: 0
A40: CP40 | B40: 40348 | C40: 1 | D40: 46146 | E40: 46157 | F40: Complete | G40: 47006700-10347691 | H40: 0.8 | I40: 46170 | J40: 46183 | K40: Not Started | L40: Upstream & Downstream conveyor not installed | M40: 0 | N40: 46170 | O40: 46183 | P40: Not Started | Q40: Upstream & Downstream conveyor not installed | R40: 0.2 | S40: 46198 | T40: 46207 | U40: Not Started | V40: Upstream & Downstream conveyor not installed | W40: 0 | X40: 46218 | Y40: 46222 | Z40: Not Started | AA40: Waiting for installation | AB40: 0 | AC40: 46223 | AD40: 46232 | AE40: Not Started | AF40: Upstream & Downstream conveyor not installed | AG40: 0 | AH40: 46243 | AI40: 46250 | AJ40: Blocked | AK40: NA | AL40: 0 | AM40: 46337 | AN40: 46343 | AO40: Not Started | AP40: 0
...

Sheet CP41
A1: CP | B1: Asset | C1: Length | D1: Prep -10% | I1: Erected 30% | N1: Anchored 10% | S1: Belting - 20% | X1: Bottom Pans - 5% | AC1: Side Guide - 20% | AH1: Netting Bracket - 5% | AM1: Run-in
D2: Start | E2: Finish | F2: Status | G2: Notes | H2: % Complete | I2: Start | J2: Finish | K2: Status | L2: Notes | M2: % Complete | N2: Start | O2: Finish | P2: Status | Q2: Notes | R2: % Complete | S2: Start | T2: Finish | U2: Status | V2: Note | W2: % Complete | X2: Start | Y2: Finish | Z2: Status | AA2: Notes | AB2: % Complete | AC2: Start | AD2: Finish | AE2: Status | AF2: Notes | AG2: % Complete | AH2: Start | AI2: Finish | AJ2: Status | AK2: Notes | AL2: % Complete | AM2: Start | AN2: Finish | AO2: Status | AP2: % Complete
A3: B-24-04663-CP41 | B3: 41035 | C3: 1 | D3: 46146 | E3: 46157 | F3: Complete | G3: Complete | H3: 0.95 | I3: 46160 | J3: 46169 | K3: Complete | L3: Complete | M3: 0.95 | N3: 46160 | O3: 46169 | P3: Complete | Q3: Complete | R3: 1 | S3: 46198 | T3: 46207 | U3: In Progress | V3: Missing Material Delivery (IQ bed) | W3: 0.5 | X3: 46218 | Y3: 46222 | Z3: Not Started | AA3: Missing Material Delivery | AB3: 0 | AC3: 46223 | AD3: 46232 | AE3: In Progress | AF3: Missing Material Delivery (IQ bed) | AG3: 0.8 | AH3: 46243 | AI3: 46250 | AJ3: Complete | AK3: NA | AL3: 1 | AM3: 46337 | AN3: 46343 | AO3: Not Started | AP3: 0
A4: B-24-04663-CP41 | B4: 41055 | C4: 1 | D4: 46146 | E4: 46157 | F4: Complete | G4: Complete | H4: 1 | I4: 46160 | J4: 46169 | K4: Complete | L4: Need adjustment with scanner | M4: 1 | N4: 46160 | O4: 46169 | P4: Complete | Q4: Need adjustment with scanner | R4: 1 | S4: 46198 | T4: 46207 | U4: Complete | V4: Complete | W4: 1 | X4: 46218 | Y4: 46222 | Z4: Not Started | AA4: 3-Phase to confirm | AB4: 0 | AC4: 46223 | AD4: 46232 | AE4: Complete | AF4: Complete | AG4: 1 | AH4: 46243 | AI4: 46250 | AJ4: Not Started | AK4: Missing Material Delivery | AL4: 0 | AM4: 46337 | AN4: 46343 | AO4: Not Started | AP4: 0
A5: B-24-04663-CP41 | B5: 41080 | C5: 1 | D5: 46146 | E5: 46157 | F5: Complete | G5: Complete | H5: 1 | I5: 46160 | J5: 46169 | K5: Complete | L5: Complete | M5: 1 | N5: 46160 | O5: 46169 | P5: Complete | Q5: Complete | R5: 1 | S5: 46198 | T5: 46207 | U5: Complete | V5: Complete | W5: 1 | X5: 46218 | Y5: 46222 | Z5: Not started | AA5: 3-Phase to confirm | AB5: 0 | AC5: 46223 | AD5: 46232 | AE5: Complete | AF5: Complete | AG5: 1 | AH5: 46243 | AI5: 46250 | AJ5: Not Started | AK5: Missing Material Delivery | AL5: 0 | AM5: 46337 | AN5: 46343 | AO5: Not Started | AP5: 0
A6: B-24-04663-CP41 | B6: 41395 | C6: 1 | D6: 46146 | E6: 46157 | F6: Complete | G6: Complete | H6: 1 | I6: 46160 | J6: 46169 | K6: Complete | L6: Complete | M6: 1 | N6: 46160 | O6: 46169 | P6: Complete | Q6: Complete | R6: 1 | S6: 46198 | T6: 46207 | U6: Complete | V6: Complete | W6: 1 | X6: 46218 | Y6: 46222 | Z6: Complete | AA6: Complete | AB6: 1 | AC6: 46223 | AD6: 46232 | AE6: Complete | AF6: Complete | AG6: 1 | AH6: 46243 | AI6: 46250 | AJ6: Complete | AK6: NA | AL6: 1 | AM6: 46337 | AN6: 46343 | AO6: Not Started | AP6: 0
A7: B-24-04663-CP41 | B7: 41445 | C7: 1 | D7: 46146 | E7: 46157 | F7: Complete | G7: Complete | H7: 1 | I7: 46160 | J7: 46169 | K7: Complete | L7: Complete | M7: 1 | N7: 46160 | O7: 46169 | P7: Complete | Q7: Complete | R7: 1 | S7: 46198 | T7: 46207 | U7: Complete | V7: Complete | W7: 1 | X7: 46218 | Y7: 46222 | Z7: Complete | AA7: Complete | AB7: 1 | AC7: 46223 | AD7: 46232 | AE7: Complete | AF7: Complete | AG7: 1 | AH7: 46243 | AI7: 46250 | AJ7: Complete | AK7: NA | AL7: 1 | AM7: 46337 | AN7: 46343 | AO7: Not Started | AP7: 0
A8: B-24-04663-CP41 | B8: 41545 | C8: 1 | D8: 46146 | E8: 46157 | F8: Complete | G8: Complete | H8: 1 | I8: 46160 | J8: 46169 | K8: Complete | L8: Complete | M8: 1 | N8: 46160 | O8: 46169 | P8: Complete | Q8: Complete | R8: 1 | S8: 46198 | T8: 46207 | U8: Complete | V8: Complete | W8: 1 | X8: 46218 | Y8: 46222 | Z8: Complete | AA8: Complete | AB8: 1 | AC8: 46223 | AD8: 46232 | AE8: In Progress | AF8: Connected Transnoem not installed | AG8: 0.7 | AH8: 46243 | AI8: 46250 | AJ8: Complete | AK8: NA | AL8: 1 | AM8: 46337 | AN8: 46343 | AO8: Not Started | AP8: 0
A9: B-24-04663-CP41 | B9: 41645 | C9: 1 | D9: 46146 | E9: 46157 | F9: Complete | G9: Complete | H9: 1 | I9: 46160 | J9: 46169 | K9: Complete | L9: Complete | M9: 1 | N9: 46160 | O9: 46169 | P9: Complete | Q9: Complete | R9: 1 | S9: 46198 | T9: 46207 | U9: Complete | V9: Complete | W9: 1 | X9: 46218 | Y9: 46222 | Z9: Complete | AA9: Complete | AB9: 1 | AC9: 46223 | AD9: 46232 | AE9: In Progress | AF9: 3-Phase to confirm | AG9: 0.1 | AH9: 46243 | AI9: 46250 | AJ9: Complete | AK9: NA | AL9: 1 | AM9: 46337 | AN9: 46343 | AO9: Not Started | AP9: 0
A10: B-24-04663-CP41 | B10: 41745 | C10: 1 | D10: 46146 | E10: 46157 | F10: Complete | G10: Complete | H10: 1 | I10: 46160 | J10: 46169 | K10: Complete | L10: Complete | M10: 1 | N10: 46160 | O10: 46169 | P10: Complete | Q10: Complete | R10: 1 | S10: 46198 | T10: 46207 | U10: Complete | V10: Complete | W10: 1 | X10: 46218 | Y10: 46222 | Z10: Complete | AA10: Complete | AB10: 1 | AC10: 46223 | AD10: 46232 | AE10: Complete | AF10: Complete | AG10: 1 | AH10: 46243 | AI10: 46250 | AJ10: Complete | AK10: NA | AL10: 1 | AM10: 46337 | AN10: 46343 | AO10: Not Started | AP10: 0
A11: B-24-04663-CP41 | B11: 41845 | C11: 1 | D11: 46146 | E11: 46157 | F11: Complete | G11: Complete | H11: 1 | I11: 46160 | J11: 46169 | K11: Complete | L11: Connected Transnorm (PBC) not on site | M11: 0 | N11: 46160 | O11: 46169 | P11: Complete | Q11: Connected Transnorm (PBC) not on site | R11: 0 | S11: 46198 | T11: 46207 | U11: Complete | V11: 3-Phase to confirm | W11: 0 | X11: 46218 | Y11: 46222 | Z11: Not Started | AA11: 3-Phase to confirm | AB11: 0 | AC11: 46223 | AD11: 46232 | AE11: Complete | AF11: 3-Phase to confirm | AG11: 0.5 | AH11: 46243 | AI11: 46250 | AJ11: Complete | AK11: NA | AL11: 1 | AM11: 46337 | AN11: 46343 | AO11: Not Started | AP11: 0
A12: B-24-04663-CP41 | B12: 41032 | C12: 1 | D12: 46146 | E12: 46157 | F12: Complete | G12: Complete | H12: 1 | I12: 46160 | J12: 46169 | K12: Not Started | L12: Connected Transnorm (PBC) not on site | M12: 0.2 | N12: 46160 | O12: 46169 | P12: Not Started | Q12: Connected Transnorm (PBC) not on site | R12: 0.2 | S12: 46198 | T12: 46207 | U12: Not Started | V12: Need update from 3-phase | W12: 0 | X12: 46218 | Y12: 46222 | Z12: Not Started | AA12: Need update from 3-phase | AB12: 0 | AC12: 46223 | AD12: 46232 | AE12: Not Started | AF12: Need update from 3-phase | AG12: 0 | AH12: 46243 | AI12: 46250 | AJ12: Complete | AK12: NA | AL12: 1 | AM12: 46337 | AN12: 46343 | AO12: Not Started | AP12: 0
A13: B-24-04663-CP41 | B13: 41040 | C13: 1 | D13: 46146 | E13: 46157 | F13: Complete | G13: Complete | H13: 1 | I13: 46160 | J13: 46169 | K13: Not Started | L13: Connected Transnorm (PBC) not on site | M13: 0 | N13: 46160 | O13: 46169 | P13: Not Started | Q13: Connected Transnorm (PBC) not on site | R13: 0 | S13: 46198 | T13: 46207 | U13: Not Started | V13: Missing Material Delivery (VB) | W13: 0 | X13: 46218 | Y13: 46222 | Z13: Not Started | AA13: Missing Material Delivery | AB13: 0 | AC13: 46223 | AD13: 46232 | AE13: Not Started | AF13: Missing Material Delivery (VB) | AG13: 1 | AH13: 46243 | AI13: 46250 | AJ13: Complete | AK13: NA | AL13: 1 | AM13: 46337 | AN13: 46343 | AO13: Not Started | AP13: 0
A14: B-24-04663-CP41 | B14: 41045 | C14: 1 | D14: 46146 | E14: 46157 | F14: Complete | G14: Complete | H14: 1 | I14: 46160 | J14: 46169 | K14: Not Started | L14: Complete | M14: 1 | N14: 46160 | O14: 46169 | P14: Not Started | Q14: Complete | R14: 1 | S14: 46198 | T14: 46207 | U14: Not Started | V14: Complete | W14: 1 | X14: 46218 | Y14: 46222 | Z14: Not Started | AA14: Missing Material Delivery | AB14: 0 | AC14: 46223 | AD14: 46232 | AE14: Not Started | AF14: Complete | AG14: 1 | AH14: 46243 | AI14: 46250 | AJ14: Complete | AK14: NA | AL14: 1 | AM14: 46337 | AN14: 46343 | AO14: Not Started | AP14: 0
A15: B-24-04663-CP41 | B15: 41065 | C15: 1 | D15: 46146 | E15: 46157 | F15: Complete | G15: Complete | H15: 1 | I15: 46160 | J15: 46169 | K15: In Progress | L15: Need adjustment with scanner | M15: 0.5 | N15: 46160 | O15: 46169 | P15: In Progress | Q15: Need adjustment with scanner | R15: 0.5 | S15: 46198 | T15: 46207 | U15: Complete | V15: Complete | W15: 1 | X15: 46218 | Y15: 46222 | Z15: Complete | AA15: Complete | AB15: 1 | AC15: 46223 | AD15: 46232 | AE15: In Progress | AF15: 3-Phase to confirm | AG15: 0.5 | AH15: 46243 | AI15: 46250 | AJ15: Not Started | AK15: Missing Material Delivery | AL15: 0 | AM15: 46337 | AN15: 46343 | AO15: Not Started | AP15: 0
A16: B-24-04663-CP41 | B16: 41085 | C16: 1 | D16: 46146 | E16: 46157 | F16: No Info ISC | G16: No Info ISC | H16: 0 | I16: 46160 | J16: 46169 | K16: Not Started | L16: Missing Material Delivery (Transnorm) | M16: 0 | N16: 46160 | O16: 46169 | P16: Not Started | Q16: Missing Material Delivery (Transnorm) | R16: 0 | S16: 46198 | T16: 46207 | U16: Not Started | V16: Missing Material Delivery (Transnorm) | W16: 0 | X16: 46218 | Y16: 46222 | Z16: Not Started | AA16: Missing Material Delivery | AB16: 0 | AC16: 46223 | AD16: 46232 | AE16: Not Started | AF16: Missing Material Delivery | AG16: 0 | AH16: 46243 | AI16: 46250 | AJ16: Not Started | AK16: Missing Material Delivery | AL16: 0 | AM16: 46337 | AN16: 46343 | AO16: Not Started | AP16: 0
A17: B-24-04663-CP41 | B17: 41115 | C17: 1 | D17: 46146 | E17: 46157 | F17: Complete | G17: Complete | H17: 1 | I17: 46160 | J17: 46169 | K17: Not Started | L17: Complete | M17: 1 | N17: 46160 | O17: 46169 | P17: Complete | Q17: Complete | R17: 1 | S17: 46198 | T17: 46207 | U17: Complete | V17: Complete | W17: 1 | X17: 46218 | Y17: 46222 | Z17: Complete | AA17: Complete | AB17: 1 | AC17: 46223 | AD17: 46232 | AE17: Complete | AF17: Complete | AG17: 1 | AH17: 46243 | AI17: 46250 | AJ17: Complete | AK17: NA | AL17: 1 | AM17: 46337 | AN17: 46343 | AO17: Not Started | AP17: 0
A18: B-24-04663-CP41 | B18: 41120 | C18: 1 | D18: 46146 | E18: 46157 | F18: Complete | G18: Complete | H18: 1 | I18: 46160 | J18: 46169 | K18: Complete | L18: Complete | M18: 1 | N18: 46160 | O18: 46169 | P18: Complete | Q18: Complete | R18: 1 | S18: 46198 | T18: 46207 | U18: Complete | V18: Complete | W18: 1 | X18: 46218 | Y18: 46222 | Z18: Complete | AA18: Complete | AB18: 1 | AC18: 46223 | AD18: 46232 | AE18: Not Started | AF18: 3-Phase to confirm | AG18: 0 | AH18: 46243 | AI18: 46250 | AJ18: Complete | AK18: NA | AL18: 1 | AM18: 46337 | AN18: 46343 | AO18: Not Started | AP18: 0
A19: B-24-04663-CP41 | B19: 41125 | C19: 1 | D19: 46146 | E19: 46157 | F19: No Info ISC | G19: No Info ISC | H19: 0 | I19: 46160 | J19: 46169 | K19: Not Started | L19: Missing Material Delivery (Transnorm) | M19: 0 | N19: 46160 | O19: 46169 | P19: Not Started | Q19: Missing Material Delivery (Transnorm) | R19: 0 | S19: 46198 | T19: 46207 | U19: Not Started | V19: Missing Material Delivery (Transnorm) | W19: 0 | X19: 46218 | Y19: 46222 | Z19: Not Started | AA19: Missing Material Delivery | AB19: 0 | AC19: 46223 | AD19: 46232 | AE19: Not Started | AF19: Missing Material Delivery | AG19: 0 | AH19: 46243 | AI19: 46250 | AJ19: Complete | AK19: NA | AL19: 1 | AM19: 46337 | AN19: 46343 | AO19: Not Started | AP19: 0
A20: B-24-04663-CP41 | B20: 41130 | C20: 1 | D20: 46146 | E20: 46157 | F20: Complete | G20: Complete | H20: 1 | I20: 46160 | J20: 46169 | K20: Not Started | L20: 3-Phase to confirm | M20: 0 | N20: 46160 | O20: 46169 | P20: Not Started | Q20: 3-Phase to confirm | R20: 0 | S20: 46198 | T20: 46207 | U20: Not Started | V20: 3-Phase to confirm | W20: 0 | X20: 46218 | Y20: 46222 | Z20: Not Started | AA20: 3-Phase to confirm | AB20: 0 | AC20: 46223 | AD20: 46232 | AE20: Not Started | AF20: 3-Phase to confirm | AG20: 0 | AH20: 46243 | AI20: 46250 | AJ20: Complete | AK20: NA | AL20: 1 | AM20: 46337 | AN20: 46343 | AO20: Not Started | AP20: 0
A21: B-24-04663-CP41 | B21: 41535 | C21: 1 | D21: 46146 | E21: 46157 | F21: Not Started | G21: CRV (PBC) | H21: 0 | I21: 46160 | J21: 46169 | K21: Not Started | L21: Missing Material Delivery (Transnorm) | M21: 0 | N21: 46160 | O21: 46169 | P21: Not Started | Q21: Missing Material Delivery (Transnorm) | R21: 0 | S21: 46198 | T21: 46207 | U21: Not Started | V21: Missing Material Delivery (Transnorm) | W21: 0 | X21: 46218 | Y21: 46222 | Z21: Not Started | AA21: Missing Material Delivery | AB21: 0 | AC21: 46223 | AD21: 46232 | AE21: Not Started | AF21: Missing Material Delivery | AG21: 0 | AH21: 46243 | AI21: 46250 | AJ21: Complete | AK21: NA | AL21: 1 | AM21: 46337 | AN21: 46343 | AO21: Not Started | AP21: 0
A22: B-24-04663-CP41 | B22: 41435 | C22: 1 | D22: 46146 | E22: 46157 | F22: In progress | G22: In progress | H22: 0.2 | I22: 46160 | J22: 46169 | K22: Not Started | L22: Missing Material Delivery (Transnorm) | M22: 0 | N22: 46160 | O22: 46169 | P22: Not Started | Q22: Missing Material Delivery (Transnorm) | R22: 0 | S22: 46198 | T22: 46207 | U22: Not Started | V22: Missing Material Delivery (Transnorm) | W22: 0 | X22: 46218 | Y22: 46222 | Z22: Not Started | AA22: Missing Material Delivery | AB22: 0 | AC22: 46223 | AD22: 46232 | AE22: Not Started | AF22: Missing Material Delivery | AG22: 0 | AH22: 46243 | AI22: 46250 | AJ22: Complete | AK22: NA | AL22: 1 | AM22: 46337 | AN22: 46343 | AO22: Not Started | AP22: 0
A23: B-24-04663-CP41 | B23: 41325 | C23: 1 | D23: 46146 | E23: 46157 | F23: In progress | G23: In progress | H23: 0.2 | I23: 46160 | J23: 46169 | K23: Not Started | L23: Missing Upstrem / Downstrem Conveyor installation | M23: 0 | N23: 46160 | O23: 46169 | P23: Not Started | Q23: Missing Upstrem / Downstrem Conveyor installation | R23: 0 | S23: 46198 | T23: 46207 | U23: Complete | V23: MDR Belted Section | W23: 1 | X23: 46218 | Y23: 46222 | Z23: Not Started | AA23: Missing Upstrem / Downstrem Conveyor installation | AB23: 0 | AC23: 46223 | AD23: 46232 | AE23: Complete | AF23: NA-prefitted SG | AG23: 1 | AH23: 46243 | AI23: 46250 | AJ23: Complete | AK23: NA | AL23: 1 | AM23: 46337 | AN23: 46343 | AO23: Not Started | AP23: 0
A24: B-24-04663-CP41 | B24: 41330 | C24: 1 | D24: 46146 | E24: 46157 | F24: Complete | G24: 5’ 6” is not on site | H24: 0.95 | I24: 46160 | J24: 46169 | K24: Not Started | L24: Missing Material Delivery | M24: 0 | N24: 46160 | O24: 46169 | P24: Not Started | Q24: Missing Material Delivery | R24: 0 | S24: 46198 | T24: 46207 | U24: Not Started | V24: Missing Material Delivery | W24: 0 | X24: 46218 | Y24: 46222 | Z24: Not Started | AA24: Missing Material Delivery | AB24: 0 | AC24: 46223 | AD24: 46232 | AE24: Not Started | AF24: Missing Material Delivery | AG24: 0 | AH24: 46243 | AI24: 46250 | AJ24: Complete | AK24: NA | AL24: 1 | AM24: 46337 | AN24: 46343 | AO24: Not Started | AP24: 0
A25: B-24-04663-CP41 | B25: 41335 | C25: 1 | D25: 46146 | E25: 46157 | F25: No Info ISC | G25: No Info ISC | H25: 0 | I25: 46160 | J25: 46169 | K25: Not Started | L25: Connected Transnorm (PBC) not on site | M25: 0 | N25: 46160 | O25: 46169 | P25: Not Started | Q25: Connected Transnorm (PBC) not on site | R25: 0 | S25: 46198 | T25: 46207 | U25: Complete | V25: Complete | W25: 1 | X25: 46218 | Y25: 46222 | Z25: Complete | AA25: Complete | AB25: 1 | AC25: 46223 | AD25: 46232 | AE25: Not Started | AF25: Complete | AG25: 1 | AH25: 46243 | AI25: 46250 | AJ25: Complete | AK25: NA | AL25: 1 | AM25: 46337 | AN25: 46343 | AO25: Not Started | AP25: 0
A26: B-24-04663-CP41 | B26: 41340 | C26: 1 | D26: 46146 | E26: 46157 | F26: Complete | G26: CRV (PBC) | H26: 0.9 | I26: 46160 | J26: 46169 | K26: Not Started | L26: Missing Material Delivery (Transnorm) | M26: 0 | N26: 46160 | O26: 46169 | P26: Not Started | Q26: Missing Material Delivery (Transnorm) | R26: 0 | S26: 46198 | T26: 46207 | U26: Not Started | V26: Missing Material Delivery (Transnorm) | W26: 0 | X26: 46218 | Y26: 46222 | Z26: Not Started | AA26: Missing Material Delivery | AB26: 0 | AC26: 46223 | AD26: 46232 | AE26: Not Started | AF26: Missing Material Delivery | AG26: 0 | AH26: 46243 | AI26: 46250 | AJ26: Complete | AK26: NA | AL26: 1 | AM26: 46337 | AN26: 46343 | AO26: Not Started | AP26: 0
A27: B-24-04663-CP41 | B27: 41345 | C27: 1 | D27: 46146 | E27: 46157 | F27: Not Started | G27: Not Started | H27: 0 | I27: 46160 | J27: 46169 | K27: Not Started | L27: Wrong colour drive (VB) | M27: 0 | N27: 46160 | O27: 46169 | P27: Not Started | Q27: Wrong colour drive (VB) | R27: 0 | S27: 46198 | T27: 46207 | U27: Not Started | V27: Wrong colour drive (VB) | W27: 0 | X27: 46218 | Y27: 46222 | Z27: Not Started | AA27: Wrong colour drive (VB) | AB27: 0 | AC27: 46223 | AD27: 46232 | AE27: Not Started | AF27: Wrong colour drive (VB) | AG27: 0 | AH27: 46243 | AI27: 46250 | AJ27: Complete | AK27: NA | AL27: 1 | AM27: 46337 | AN27: 46343 | AO27: Not Started | AP27: 0
A28: B-24-04663-CP41 | B28: 41375 | C28: 1 | D28: 46146 | E28: 46157 | F28: Not Started | G28: Not Started | H28: 0 | I28: 46160 | J28: 46169 | K28: Not Started | L28: Missing Upstrem / Downstrem Conveyor installation | M28: 0 | N28: 46160 | O28: 46169 | P28: Not Started | Q28: Missing Upstrem / Downstrem Conveyor installation | R28: 0 | S28: 46198 | T28: 46207 | U28: Complete | V28: MDR Belted Section | W28: 1 | X28: 46218 | Y28: 46222 | Z28: Not Started | AA28: Missing Upstrem / Downstrem Conveyor installation | AB28: 0 | AC28: 46223 | AD28: 46232 | AE28: Complete | AF28: NA-prefitted SG | AG28: 1 | AH28: 46243 | AI28: 46250 | AJ28: Complete | AK28: NA | AL28: 1 | AM28: 46337 | AN28: 46343 | AO28: Not Started | AP28: 0
A29: B-24-04663-CP41 | B29: 41380 | C29: 1 | D29: 46146 | E29: 46157 | F29: Not Started | G29: Not Started | H29: 0 | I29: 46160 | J29: 46169 | K29: Not Started | L29: 3-Phase to confirm | M29: 0 | N29: 46160 | O29: 46169 | P29: Not Started | Q29: 3-Phase to confirm | R29: 0 | S29: 46198 | T29: 46207 | U29: Not Started | V29: 3-Phase to confirm | W29: 0 | X29: 46218 | Y29: 46222 | Z29: Not Started | AA29: 3-Phase to confirm | AB29: 0 | AC29: 46223 | AD29: 46232 | AE29: Not Started | AF29: 3-Phase to confirm | AG29: 0 | AH29: 46243 | AI29: 46250 | AJ29: Complete | AK29: NA | AL29: 1 | AM29: 46337 | AN29: 46343 | AO29: Not Started | AP29: 0
A30: B-24-04663-CP41 | B30: 41385 | C30: 1 | D30: 46146 | E30: 46157 | F30: No Info ISC | G30: No Info ISC | H30: 0 | I30: 46160 | J30: 46169 | K30: Not Started | L30: 3-Phase to confirm | M30: 0 | N30: 46160 | O30: 46169 | P30: Not Started | Q30: 3-Phase to confirm | R30: 0 | S30: 46198 | T30: 46207 | U30: Not Started | V30: 3-Phase to confirm | W30: 0 | X30: 46218 | Y30: 46222 | Z30: Not Started | AA30: 3-Phase to confirm | AB30: 0 | AC30: 46223 | AD30: 46232 | AE30: Complete | AF30: 3-Phase to confirm | AG30: 0 | AH30: 46243 | AI30: 46250 | AJ30: Complete | AK30: NA | AL30: 1 | AM30: 46337 | AN30: 46343 | AO30: Not Started | AP30: 0
A31: B-24-04663-CP41 | B31: 41390 | C31: 1 | D31: 46146 | E31: 46157 | F31: Not Started | G31: Not Started | H31: 0 | I31: 46160 | J31: 46169 | K31: Not Started | L31: Missing Material Delivery (Transnorm) | M31: 0 | N31: 46160 | O31: 46169 | P31: Not Started | Q31: Missing Material Delivery (Transnorm) | R31: 0 | S31: 46198 | T31: 46207 | U31: Not Started | V31: Missing Material Delivery (Transnorm) | W31: 0 | X31: 46218 | Y31: 46222 | Z31: Not Started | AA31: Missing Material Delivery | AB31: 0 | AC31: 46223 | AD31: 46232 | AE31: Not Started | AF31: Missing Material Delivery | AG31: 0 | AH31: 46243 | AI31: 46250 | AJ31: Complete | AK31: NA | AL31: 1 | AM31: 46337 | AN31: 46343 | AO31: Not Started | AP31: 0
A32: B-24-04663-CP41 | B32: 41425 | C32: 1 | D32: 46146 | E32: 46157 | F32: Complete | G32: is not on site | H32: 1 | I32: 46160 | J32: 46169 | K32: Not Started | L32: Missing Upstrem / Downstrem Conveyor installation | M32: 0 | N32: 46160 | O32: 46169 | P32: Not Started | Q32: Missing Upstrem / Downstrem Conveyor installation | R32: 0 | S32: 46198 | T32: 46207 | U32: Complete | V32: MDR Belted Section | W32: 1 | X32: 46218 | Y32: 46222 | Z32: Not Started | AA32: Missing Upstrem / Downstrem Conveyor installation | AB32: 0 | AC32: 46223 | AD32: 46232 | AE32: Complete | AF32: NA-prefitted SG | AG32: 1 | AH32: 46243 | AI32: 46250 | AJ32: Complete | AK32: NA | AL32: 1 | AM32: 46337 | AN32: 46343 | AO32: Not Started | AP32: 0
A33: B-24-04663-CP41 | B33: 41430 | C33: 1 | D33: 46146 | E33: 46157 | F33: Complete | G33: Complete | H33: 1 | I33: 46160 | J33: 46169 | K33: Not Started | L33: Connected Transnorm (PBC) not on site | M33: 0 | N33: 46160 | O33: 46169 | P33: Not Started | Q33: Connected Transnorm (PBC) not on site | R33: 0 | S33: 46198 | T33: 46207 | U33: Complete | V33: Complete | W33: 1 | X33: 46218 | Y33: 46222 | Z33: Complete | AA33: Complete | AB33: 1 | AC33: 46223 | AD33: 46232 | AE33: Complete | AF33: Complete | AG33: 1 | AH33: 46243 | AI33: 46250 | AJ33: Complete | AK33: NA | AL33: 1 | AM33: 46337 | AN33: 46343 | AO33: Not Started | AP33: 0
A34: B-24-04663-CP41 | B34: 41440 | C34: 1 | D34: 46146 | E34: 46157 | F34: Not Started | G34: Not Started | H34: 0 | I34: 46160 | J34: 46169 | K34: Complete | L34: Complete | M34: 1 | N34: 46160 | O34: 46169 | P34: Complete | Q34: Complete | R34: 1 | S34: 46198 | T34: 46207 | U34: Complete | V34: Complete | W34: 1 | X34: 46218 | Y34: 46222 | Z34: Complete | AA34: Complete | AB34: 1 | AC34: 46223 | AD34: 46232 | AE34: Complete | AF34: Connected Transnorm (PBC) not on site | AG34: 0.7 | AH34: 46243 | AI34: 46250 | AJ34: Complete | AK34: NA | AL34: 1 | AM34: 46337 | AN34: 46343 | AO34: Not Started | AP34: 0
